<?xml version="1.0"?>

<!-- 
	Parts of the URDF and all the .stl files taken from https://defiant.homedns.org/gitweb/?p=ros_wild_thumper.git
-->

<robot name="wild_thumper" xmlns:xacro="http://ros.org/wiki/xacro">
	<xacro:property name="PI" value="3.1415926535897931" />

	<material name="wtgrey">
		<color rgba="0.5 0.5 0.5 0.5"/>
	</material>
	<material name="wtred">
		<color rgba="1 0 0 1"/>
	</material>
	<material name="wtblack">
		<color rgba="0 0 0 1"/>
	</material>
	<material name="wtgreen">
		<color rgba="0 1 0 0.8"/>
	</material>

	<link name="base_footprint">
		<visual>
			<geometry>
				<box size="0.28 0.31 0.000001"/>
			</geometry>
			<material name="wtgrey"/>
		</visual>
	</link>

	<link name="base_link">
		<collision>
			<geometry>
				<box size="0.23 0.12 0.09"/>
			</geometry>
		</collision>
		<visual>
			<origin xyz="-0.00275 0 0" rpy="0 0 0"/>
			<geometry>
				<mesh filename="package://wild_thumper_ros/meshes/wild_thumper_4wd.stl" />
			</geometry>
		</visual>
		<inertial>
			<origin xyz="-0.00275 0 -0.02" rpy="0 0 0"/>
			<mass value="2.5"/>
			<inertia ixx="0.012708" ixy="0.0" ixz="0.0" iyy="0.0084375" iyz="0.0" izz="0.017771"/>
		</inertial>
	</link>

	<link name="mounting_plate">
		<visual>
			<geometry>
				<box size="0.23 0.12 0.001"/>
			</geometry>
		</visual>
	</link>


	<joint name="base_link_joint" type="fixed">
		<parent link="base_footprint"/>
		<child link="base_link"/>
		<origin xyz="0.0 0.0 0.082" rpy="0 0 0"/>
	</joint>

	<joint name="mounting_plate_joint" type="fixed">
		<parent link="base_link"/>
		<child link="mounting_plate"/>
		<origin xyz="0.0 0.0 0.044" rpy="0 0 0"/>

    </joint>

	<xacro:macro name="wheel" params="pos side xyz rpy"> 
		<link name="${pos}_${side}_wheel">
			<visual>
				<origin xyz="0 0 0" rpy="0 0 0"/>
				<geometry>
					<mesh filename="package://wild_thumper_ros/meshes/wheel_${side}.stl" />
				</geometry>
			</visual>
			<collision>
				<origin xyz="0 0 0" rpy="${PI/2} 0 0"/>
				<geometry>
					<cylinder radius="0.06" length="0.06"/>
				</geometry>
			</collision>
			<inertial>
				<origin xyz="0 0 0" rpy="0 0 0"/>
				<mass value="0.2"/>
				<inertia ixx="0.00024" ixy="0" ixz="0" iyy="0.00036" iyz="0" izz="0.00024"/>
			</inertial>
		</link>

		<gazebo reference="${pos}_${side}_wheel">
			<mu1 value="1.0"/>
			<mu2 value="0.2"/>
			<kp value="1000000000000.0" />
			<kd value="0.0" />
			<fdir1 value="0 1 0"/>
			<minDepth>0.005</minDepth>
		</gazebo>

        <joint name="${pos}_${side}" type="continuous">
			<parent link="base_link"/>
			<child link="${pos}_${side}_wheel"/>
			<axis xyz="0 1 0"/>
			<origin xyz="${xyz}" rpy="${rpy}"/>
		</joint>

	</xacro:macro>

	<xacro:wheel pos="rear" side="left"   xyz="-0.07525  0.12 -0.025" rpy="${-5*PI/180} 0 0" />
	<xacro:wheel pos="rear" side="right"  xyz="-0.07525 -0.12 -0.025" rpy="${5*PI/180} 0 0" />
	<xacro:wheel pos="front" side="left"  xyz=" 0.07525  0.12 -0.025" rpy="${-5*PI/180} 0 0" />
	<xacro:wheel pos="front" side="right" xyz=" 0.07525 -0.12 -0.025" rpy="${5*PI/180} 0 0" />

	<gazebo>
		<plugin name="gazebo_ros_control" filename="libgazebo_ros_control.so">
			<robotNamespace>/</robotNamespace>
			<robotSimType>gazebo_ros_control/DefaultRobotHWSim</robotSimType>
		</plugin>

	<transmission name="front_right_trans" type="SimpleTransmission">
		<type>transmission_interface/SimpleTransmission</type>
		<joint name="front_right">
			<hardwareInterface>hardware_interface/VelocityJointInterface</hardwareInterface>
		</joint>
		<actuator name="front_right_motor">
			<mechanicalReduction>1</mechanicalReduction>
		</actuator>
	</transmission>

	<transmission name="front_left_trans" type="SimpleTransmission">
		<type>transmission_interface/SimpleTransmission</type>
		<joint name="front_left">
			<hardwareInterface>hardware_interface/VelocityJointInterface</hardwareInterface>
		</joint>
		<actuator name="front_left_motor">
			<mechanicalReduction>1</mechanicalReduction>
		</actuator>
	</transmission>

	<transmission name="rear_right_trans" type="SimpleTransmission">
		<type>transmission_interface/SimpleTransmission</type>
		<joint name="rear_right">
			<hardwareInterface>hardware_interface/VelocityJointInterface</hardwareInterface>
		</joint>
		<actuator name="rear_right_motor">
			<mechanicalReduction>1</mechanicalReduction>
		</actuator>
	</transmission>

	<transmission name="rear_left_trans" type="SimpleTransmission">
		<type>transmission_interface/SimpleTransmission</type>
		<joint name="rear_left">
			<hardwareInterface>hardware_interface/VelocityJointInterface</hardwareInterface>
		</joint>
		<actuator name="rear_left_motor">
			<mechanicalReduction>1</mechanicalReduction>
		</actuator>
	</transmission>

</robot>
